Workbook

Sheet Laporan
A1: General Ledger | F1: AJP | K1: Neraca Saldo (Balance Sheet)
A2: Tanggal | B2: Nama Akun | C2: Debit | D2: Credit | F2: Tanggal | G2: Nama Akun | H2: Debit | I2: Kredit | K2: Periode Akhir Jan 2017
A3: 46023 | B3: Kas | C3: 20000000 | F3: 46387 | G3: Beban Sewa | H3: 3000000 | K3: Aktiva(Assets) | N3: Passiva
B4: Modal | D4: 20000000 | G4: Sewa dibayar dimuka | I4: 3000000 | K4: Aktiva Lancar | N4: Hutang
A5: 46024 | B5: Peralatan | C5: 3000000 | F5: 46387 | G5: Beban Asuransi | H5: 5000000 | K5: Kas | L5: =G43 -> 23500000 | N5: Hutang Lancar
B6: Perlengkapan | C6: 500000 | G6: Asuransi dibayar dimuka | I6: 5000000 | K6: Piutang | L6: =G48 -> 3000000 | N6: Hutang Usaha | O6: =H50 -> 1000000
B7: Kas | D7: =C5+C6 -> 3500000 | F7: 46387 | G7: Pendapatan diterima dimuka | H7: 4000000 | K7: Perlengkapan | L7: =G46 -> 1200000 | N7: Pendapatan Diterima Dimuka | O7: =H55 -> 8000000
B8: Sewa Dibayar Dimuka | C8: 3000000 | G8: Pendapatan | I8: 4000000 | K8: Asuransi Dibayar Dimuka | L8: =G54 -> 7000000 | N8: Hutang Gaji | O8: =H58 -> 3500000
B9: Kas | D9: 3000000 | F9: 46387 | G9: Beban Gaji | H9: 3500000 | K9: Sewa Dibayar Dimuka | L9: =G47 -> 0 | N9: Hutang Jangka Panjang
A10: 46025 | B10: Piutang | C10: 5000000 | G10: Hutang Gaji | I10: 3500000 | K10: Total Aktiva Lancar | M10: =SUM(L5:L9) -> 34700000 | N10: Hutang Bank | O10: 0
B11: Pendapatan | D11: 5000000 | F11: 46387 | G11: Beban penyusutan peralatan | H11: ='Perincian Laporan'!C9 -> 600000 | K11: Aktiva Tetap | N11: Total Utang | P11: =SUM(O5:O10) -> 12500000
A12: 46028 | B12: Piutang | C12: 3000000 | G12: Akumulasi penyusutan peralatan | I12: ='Perincian Laporan'!C9 -> 600000 | K12: Tanah
B13: Pendapatan | D13: 3000000 | F13: 46387 | G13: Beban Perlengkapan | H13: ='Perincian Laporan'!C17-'Perincian Laporan'!C18 -> 1300000 | K13: Bangunan | N13: Modal | P13: =C80 -> 24600000
A14: 46029 | B14: Perlengkapan | C14: 1000000 | G14: Perlengkapan | I14: ='Perincian Laporan'!C17-'Perincian Laporan'!C18 -> 1300000 | K14: Akumulasi Penyusutan Bangunan
B15: Hutang | D15: 1000000 | K15: Peralatan | L15: =G45 -> 3000000
A16: 46031 | B16: Piutang | C16: 9000000 | K16: Akumulasi Penyusutan Peralatan | M16: =-H60 -> -600000
B17: Pendapatan | D17: 9000000 | K17: Total Aktiva Tetap | M17: =SUM(SUM(L12:L16),SUM(M12:M16)) -> 2400000
B18: Kas | C18: 3000000 | K18: Total Aktiva | M18: =M10+M17 -> 37100000 | N18: Total Utang & Modal | P18: =P11+P13 -> 37100000
B19: Piutang | D19: 3000000
A20: 46043 | B20: Kas | C20: 4000000
B21: Pendapatan | D21: 4000000
A22: 46044 | B22: Kas | C22: 5000000
B23: Piutang | D23: 5000000
A24: 46045 | B24: Perlengkapan | C24: 1000000
B25: Kas | D25: 1000000
A26: 46046 | B26: Kas | C26: 6000000
B27: Piutang | D27: 6000000
A28: 46047 | B28: Beban Gaji | C28: 3000000
B29: Kas | D29: 3000000
A30: 46048 | B30: Prive | C30: 1500000
B31: Kas | D31: 1500000
A32: 46050 | B32: Beban Utilitas | C32: 2500000
B33: Kas | D33: 2500000
A34: 46235 | B34: Asuransi Dibayar Dimuka | C34: 12000000
B35: Kas | D35: 12000000
A36: 46266 | B36: Kas | C36: 12000000
B37: Pendapatan Diterima Dimuka | D37: 12000000
A38: Total | C38: =SUM(C2:C37) -> 94500000 | D38: =SUM(D2:D37) -> 94500000
B40: Trial Balance
B41: Nama Akun | C41: Jurnal Umum | E41: Ayat Jurnal Penyesuaian | G41: Saldo Akhir
...

Sheet Perincian Laporan
A1: Perincian Penyusutan Peralatan
A3: Peralatan
A4: Tanggal Perolehan | B4: Tahun | C4: Nilai Perolehan | D4: Disusutkan(Tahun) | E4: Nilai Penyusutan Pertahun
A5: 46024 | B5: 2017 | C5: =Laporan!C5 -> 3000000 | D5: 5 | E5: =C5/D5 -> 600000
A8: Total Nilai Peralatan | C8: =C5 -> 3000000
A9: Penyusutan Hingga 2017 | C9: =E5 -> 600000
A10: Nilai Buku 2017 | C10: =C8-C9 -> 2400000
A12: Perlengkapan
A13: Tanggal Perolehan | B13: Tahun | C13: Nilai Perolehan
A14: 46024 | B14: 2017 | C14: =Laporan!C6 -> 500000
A15: 46029 | B15: 2017 | C15: =Laporan!C14 -> 1000000
A16: 46045 | B16: 2017 | C16: =Laporan!C24 -> 1000000
A17: Total | C17: =SUM(C14:C16) -> 2500000
A18: Sisah Stok | C18: 1200000

Sheet Buku Besar
A1: Kas | I1: Neraca Saldo
A2: Tanggal | B2: Keterangan | C2: Ref | D2: Debit | E2: Kredit | F2: Saldo | I2: No Akun | J2: Jurnal | K2: Debit | L2: Kredit
F3: Debit | G3: Kredit | I3: 1.1 | J3: =Laporan!B43 -> Kas | K3: =F16 -> 23500000
A4: 42736 | B4: Setoran Awal | C4: JU | D4: 20000000 | F4: =D4-E4 -> 20000000 | I4: 1.2 | J4: =Laporan!B48 -> Piutang | K4: =F26 -> 3000000
A5: 42737 | B5: Pembelian Peralatan dan Perlengkapan | C5: JU | E5: 3500000 | F5: =F4+D5-E5 -> 16500000 | I5: 1.3 | J5: =Laporan!B46 -> Perlengkapan | K5: =F34 -> 1200000
A6: 42737 | B6: Pembayaran Sewa Dibayar Dimuka | C6: JU | E6: 3000000 | F6: =F5+D6-E6 -> 13500000 | I6: 1.5 | J6: =Laporan!B54 -> Asuransi Dibayar Dimuka | K6: =F40 -> 7000000
A7: 42744 | B7: Menerima Piutang | C7: JU | D7: 3000000 | F7: =F6+D7-E7 -> 16500000 | I7: 1.6 | J7: =Laporan!B47 -> Sewa Dibayar Dimuka | K7: =F46 -> 0
A8: 42756 | B8: Menerima Pendapatan | C8: JU | D8: 4000000 | F8: =F7+D8-E8 -> 20500000 | I8: 1.7 | J8: =Laporan!B45 -> Peralatan | K8: =F51 -> 3000000
A9: 42757 | B9: Menerima Piutang | C9: JU | D9: 5000000 | F9: =F8+D9-E9 -> 25500000 | I9: 1.7.1 | J9: =Laporan!B60 -> Akumulasi penyusutan peralatan | L9: =G56 -> 600000
A10: 42758 | B10: Pembelian Perlengkapan | C10: JU | E10: 1000000 | F10: =F9+D10-E10 -> 24500000 | I10: 2.1 | J10: =Laporan!B50 -> Hutang | L10: =G61 -> 1000000
A11: 42759 | B11: Menerima Piutang | C11: JU | D11: 6000000 | F11: =F10+D11-E11 -> 30500000 | I11: 2.2 | J11: =Laporan!B55 -> Pendapatan Diterima Dimuka | L11: =G67 -> 8000000
A12: 42760 | B12: Membayar Biaya Gaji | C12: JU | E12: 3000000 | F12: =F11+D12-E12 -> 27500000 | I12: 2.3 | J12: =Laporan!B58 -> Hutang Gaji | L12: =G72 -> 3500000
A13: 42761 | B13: Pengambilan Prive | C13: JU | E13: 1500000 | F13: =F12+D13-E13 -> 26000000 | I13: 3.1 | J13: =Laporan!B44 -> Modal | L13: =G79 -> 24600000
A14: 42763 | B14: Membayar Biaya Utilitas | C14: JU | E14: 2500000 | F14: =F13+D14-E14 -> 23500000 | I14: 3.2 | J14: =Laporan!B52 -> Prive | K14: =F85 -> 0
A15: 42948 | B15: Membayar Asuransi Dibayar Dimuka | C15: JU | E15: 12000000 | F15: =F14+D15-E15 -> 11500000 | I15: 4.1 | J15: =Laporan!B49 -> Pendapatan | L15: =G95 -> 0
A16: 42979 | B16: Menerima Pendapatan Diterima Dimuka | C16: JU | D16: 12000000 | F16: =F15+D16-E16 -> 23500000 | I16: 5.1 | J16: =Laporan!B53 -> Beban Utilitas | K16: =F101 -> 0
I17: 5.2 | J17: =Laporan!B51 -> Beban Gaji | K17: =F108 -> 0
A18: Piutang | I18: 5.3 | J18: =Laporan!B56 -> Beban Sewa | K18: =F114 -> 0
A19: Tanggal | B19: Keterangan | C19: Ref | D19: Debit | E19: Kredit | F19: Saldo | I19: 5.4 | J19: =Laporan!B57 -> Beban Asuransi | K19: =F120 -> 0
F20: Debit | G20: Kredit | I20: 5.5 | J20: =Laporan!B59 -> Beban penyusutan peralatan | K20: =F126 -> 0
A21: 42738 | B21: Piutang Cat Mobil Pak Joko | C21: JU | D21: 5000000 | F21: =D21-E21 -> 5000000 | I21: 5.6 | J21: =Laporan!B61 -> Beban Perlengkapan | K21: =F132 -> 0
A22: 42741 | B22: Piutang Pak Agung | C22: JU | D22: 3000000 | F22: =F21+D22-E22 -> 8000000 | J22: Ikhtisar Laba Rugi | L22: =G139 -> 0
A23: 42744 | B23: Piutang Orderan Job | C23: JU | D23: 9000000 | F23: =F22+D23-E23 -> 17000000 | K23: =SUM(K3:K22) -> 37700000 | L23: =SUM(L3:L22) -> 37700000
A24: 42744 | B24: Piutang Tanggal 9 Jan 2017 Dibayar | C24: JU | E24: 3000000 | F24: =F23+D24-E24 -> 14000000
A25: 42757 | B25: Piutang Tanggal 3 Jan 2017 Dibayar | C25: JU | E25: 5000000 | F25: =F24+D25-E25 -> 9000000
A26: 42759 | B26: Piutang Tanggal 9 Jan 2017 Dibayar | C26: JU | E26: 6000000 | F26: =F25+D26-E26 -> 3000000
A28: Perlengkapan
A29: Tanggal | B29: Keterangan | C29: Ref | D29: Debit | E29: Kredit | F29: Saldo
F30: Debit | G30: Kredit
A31: 42737 | B31: Pembelian Perlengkapan Secara Tunai | C31: JU | D31: 500000 | F31: =D31-E31 -> 500000
A32: 42742 | B32: Pembelian Perlengkapan Dibayar Akhir Bulan | C32: JU | D32: 1000000 | F32: =F31+D32-E32 -> 1500000
A33: 42758 | B33: Pembelian Perlengkapan Secara Tunai | C33: JU | D33: 1000000 | F33: =F32+D33-E33 -> 2500000
A34: 43100 | B34: Penyesuaaian Perlengkapan | C34: AJP | E34: 1300000 | F34: =F33+D34-E34 -> 1200000
A36: Asuransi Dibayar Dimuka
A37: Tanggal | B37: Keterangan | C37: Ref | D37: Debit | E37: Kredit | F37: Saldo
F38: Debit | G38: Kredit
A39: 42948 | B39: Pembayaran Asuransi Dibayar Dimuka Secara Tunai | C39: JU | D39: 12000000 | F39: =D39-E39 -> 12000000
A40: 43100 | B40: Penyesuaian Asuransi Dibayar Dimuka | C40: AJP | E40: 5000000 | F40: =F39+D40-E40 -> 7000000
A42: Sewa Dibayar Dimuka
A43: Tanggal | B43: Keterangan | C43: Ref | D43: Debit | E43: Kredit | F43: Saldo
...

Sheet Buku Besar Pembantu
A1: Pembantu Piutang
A3: Pak Joko
A4: Tanggal | B4: Keterangan | C4: Ref | D4: Debit | E4: Kredit | F4: Saldo
F5: Debit | G5: Kredit
A6: 42738 | B6: Menerima Piutang | C6: JU | D6: 5000000 | F6: =D6-E6 -> 5000000
A7: 42757 | B7: Pelunasan Piutang | C7: JU | E7: 5000000 | F7: =F6+D7-E7 -> 0
A9: Pak Agung
A10: Tanggal | B10: Keterangan | C10: Ref | D10: Debit | E10: Kredit | F10: Saldo
F11: Debit | G11: Kredit
A12: 42741 | B12: Menerima Piutang | C12: JU | D12: 3000000 | F12: =D12-E12 -> 3000000
A14: Orderan
A15: Tanggal | B15: Keterangan | C15: Ref | D15: Debit | E15: Kredit | F15: Saldo
F16: Debit | G16: Kredit
A17: 42744 | B17: Menerima Piutang | C17: JU | D17: 9000000 | F17: =D17-E17 -> 9000000
A18: 42744 | B18: Pelunasan Piutang | C18: JU | E18: 3000000 | F18: =F17+D18-E18 -> 6000000
A19: 42759 | B19: Pelunasan Piutang | C19: JU | E19: 6000000 | F19: =F18+D19-E19 -> 0

Sheet Jurnal Penutup
A1: Jurnal Penutup
A2: Tanggal | B2: Nama Akun | C2: Debit | D2: Credit
A3: 43100 | B3: Pendapatan Usaha | C3: =Laporan!C65 -> 25000000
B4: Ikhtisar Laba Rugi | D4: =Laporan!C65 -> 25000000
B6: Ikhtisar Laba Rugi | C6: =SUM(D7:D12) -> 18900000
B7: Beban Utilitas | D7: =Laporan!C67 -> 2500000
B8: Beban Gaji | D8: =Laporan!C68 -> 6500000
B9: Beban Sewa | D9: =Laporan!C69 -> 3000000
B10: Beban Asuransi | D10: =Laporan!C70 -> 5000000
B11: Beban Penyusutan Peralatan | D11: =Laporan!C71 -> 600000
B12: Beban Perlengkapan | D12: =Laporan!C72 -> 1300000
B14: Ikhtisar Laba Rugi | C14: =Laporan!C74 -> 6100000
B15: Modal | D15: =Laporan!C74 -> 6100000
B17: Modal | C17: =Laporan!G52 -> 1500000
B18: Prive | D18: =Laporan!G52 -> 1500000
C19: =SUM(C3:C18) -> 51500000 | D19: =SUM(D3:D18) -> 51500000

Sheet Neraca Awal Periode Baru
A1: Neraca Saldo (Balance Sheet)
A2: Awal Periode 2018
A3: Aktiva(Assets) | D3: Passiva
A4: Aktiva Lancar | D4: Hutang
A5: Kas | B5: ='Buku Besar'!K3 -> 23500000 | D5: Hutang Lancar
A6: Piutang | B6: ='Buku Besar'!K4 -> 3000000 | D6: Hutang Usaha | E6: ='Buku Besar'!L10 -> 1000000
A7: Perlengkapan | B7: ='Buku Besar'!K5 -> 1200000 | D7: Pendapatan Diterima Dimuka | E7: ='Buku Besar'!L11 -> 8000000
A8: Asuransi Dibayar Dimuka | B8: ='Buku Besar'!K6 -> 7000000 | D8: Hutang Gaji | E8: ='Buku Besar'!L12 -> 3500000
A9: Sewa Dibayar Dimuka | B9: ='Buku Besar'!K7 -> 0 | D9: Hutang Jangka Panjang
A10: Total Aktiva Lancar | C10: =SUM(B5:B9) -> 34700000 | D10: Hutang Bank | E10: 0
A11: Aktiva Tetap | D11: Total Utang | F11: =SUM(E5:E10) -> 12500000
A12: Tanah
A13: Bangunan | D13: Modal | F13: ='Buku Besar'!L13 -> 24600000
A14: Akumulasi Penyusutan Bangunan
A15: Peralatan | B15: ='Buku Besar'!K8 -> 3000000
A16: Akumulasi Penyusutan Peralatan | C16: =-'Buku Besar'!L9 -> -600000
A17: Total Aktiva Tetap | C17: =SUM(SUM(B12:B16),SUM(C12:C16)) -> 2400000
A18: Total Aktiva | C18: =C10+C17 -> 37100000 | D18: Total Utang & Modal | F18: =F11+F13 -> 37100000
